Workbook

Sheet Static Data
A1: Deviation Area List | B1: Complaint Area List
A2: QC Testing | B2: Strength
A3: QC Samples | B3: Product Mixup
A4: QC Annual Performance Qualification | B4: Product Appearance
A5: QC Standards | B5: Pharmacovigilance
A6: Internal Audits | B6: AE / ADRs
A7: Third Party Product Release | B7: Product Packaging
A8: Product Processing | B8: Product Formulation
A9: Product Manufacturing | B9: Delivery
A10: Temperature Excursion | B10: Product Scent
A11: Labelling | B11: Labelling / PIL
A12: Cleaning | B12: Documentation
... A19: Temperature Monitoring | B19: Other
A20: Equipment
A21: Dispatch Cleaning Procedure
A22: Stability
A23: CBPM Shipment
A24: Product Mixup
A25: Equipment Validation
A26: Transport
A27: Validation
A28: Product Formulation
A29: Business Central
A30: Other

Sheet Deviation RC Data
D1: Where the deviation happened | P1: Root Causes Identified | AI1: Department Responsible for Root Causes
AI2: Quality Assurance | AL2: Other Departments
A3: Document Reference | B3: Date Raised | C3: Department that logged deviation | D3: Finance | E3: Procurement | F3: Customer Service | G3: R&D | H3: SLT | I3: Production | J3: Dispatch | K3: QA | L3: QC | M3: BMR generation | N3: Final release | O3: Deviation area (Processes and activities) | P3: Human error | Q3: Formulation issue | R3: Material / Consumables Availability | S3: Inadequate Material / Consumables | T3: Communication issue | U3: Inadequate Planning | V3: Procedure is defficient | W3: Equipment Fault - wear and tear | X3: Inadequate storage | Y3: No procedure in place | Z3: Equipment availability | AA3: Training / skills / knowledge issue | AB3: Staff Availability | AC3: IT/System Issues | AD3: Facility Issue | AE3: Environmental Conditions | AF3: Validation /Calibration | AG3: GDocP not followed | AH3: Other | AI3: Final Release | AJ3: BMR | AK3: QA2 | AL3: Production2 | AM3: QC2 | AN3: Dispatch2 | AO3: R&D2 | AP3: Customer Service2 | AQ3: CBPM | AR3: Procurement2 | AS3: SLT2 | AT3: Finance2
A4: DEV.2024.001 | B4: 45300 | C4: QC | L4: x | O4: QC testing | V4: x | AM4: x
A5: DEV.2024.002 | B5: 45300 | C5: QC | L5: x | O5: QC samples | W5: x | AM5: x
A6: DEV.2024.003 | B6: 45306 | C6: QC | L6: x | O6: QC Annual performance qualification | AF6: x | AM6: x
A7: DEV.2024.004 | B7: 45307 | C7: QC | L7: x | O7: QC samples | X7: x | AM7: x
A8: DEV.2024.005 | B8: 45307 | C8: QC | L8: x | O8: QC Standards | P8: x | AM8: x
A9: DEV.2024.006 | B9: 45308 | C9: QA | K9: x | O9: Internal Audits | V9: x | AK9: x
A10: DEV.2024.007 | B10: 45308 | C10: QA | N10: x | O10: Third party Product Release | V10: x | Y10: x | AA10: x | AL10: x | AO10: x
A11: DEV.2024.008 | B11: 45310 | C11: Production | N11: x | O11: Product processing | T11: x | V11: x | AL11: x | AN11: x
A12: DEV.2024.009 | B12: 45315 | C12: Production, R&D | K12: x | O12: Product manufacturing | Q12: x | R12: x | AO12: x
A13: DEV.2024.010 | B13: 45327 | C13: QA | K13: x | O13: Temperature excursion | Z13: x | AA13: x | AK13: x
A14: DEV.2024.011 | B14: 45327 | C14: QC | L14: x | O14: QC testing | AF14: x | AM14: x
A15: DEV.2024.012 | B15: 45327 | C15: QC | L15: x | O15: Labelling | V15: x | AM15: x
A16: DEV.2024.013 | B16: 45337 | C16: QC | L16: x | O16: Cleaning | AH16: Root cause not determined
A17: DEV.2024.014 | B17: 45350 | C17: QA | K17: x | O17: Documentation | V17: x | AA17: x | AK17: x
A18: DEV.2024.015 | B18: 45351 | C18: QA | N18: x | O18: Product storage | T18: x | Z18: x
A19: DEV.2024.016 | B19: 45356 | C19: Production | I19: x | O19: Data integrity | V19: x | Y19: x | AL19: x
A20: DEV.2024.017 | B20: 45356 | C20: QA | K20: x | O20: Environmental Monitoring | Z20: x | AA20: x | AB20: x | AK20: x
A21: DEV.2024.018 | B21: 45359 | C21: QA | N21: x | O21: Non-Conforming Product | P21: x | V21: x | AA21: x | AJ21: x
A22: DEV.2024.019 | B22: 45359 | C22: Production | I22: x | O22: Product manufacturing | P22: x | AA22: x | AL22: x
A23: DEV.2024.020 | B23: 45372 | C23: QA | I23: x | O23: Environmental Monitoring | V23: x | AD23: x | AE23: x | AL23: x
A24: DEV.2024.021 | B24: 45376 | C24: QA | M24: x | O24: Product formulation | P24: x | Q24: x | T24: x | AO24: x
A25: DEV.2024.022 | B25: 45384 | C25: QA | I25: x | O25: Non-Conforming Product | Q25: x | AO25: x
A26: DEV.2024.023 | B26: 45384 | C26: QA | I26: x | M26: x | O26: Non-Conforming Product | AA26: x | AJ26: x
A27: DEV.2024.024 | B27: 45390 | C27: QC | L27: x | O27: QC testing | AB27: x | AF27: x | AM27: x
A28: DEV.2024.025 | B28: 45390 | C28: QA | M28: x | O28: Product formulation | Q28: x | AA28: x | AO28: x
A29: DEV.2024.026 | B29: 45390 | C29: Production | I29: x | O29: Documentation | P29: x | V29: x | AL29: x
A30: DEV.2024.027 | B30: 45391 | C30: QA | I30: x | N30: x | O30: Documentation | T30: x | V30: x | Y30: x | AM30: x
A31: DEV.2024.028 | B31: 45392 | C31: QA | M31: x | O31: Non-Conforming Product | P31: x | Y31: x | AA31: x | AJ31: x | AL31: x
A32: DEV.2024.029 | B32: 45394 | C32: QC | L32: x | O32: QC testing | AF32: x | AH32: Material | AM32: x
A33: DEV.2024.030 | B33: 45400 | C33: QA | K33: x | O33: Event Logging Procedure | V33: x | AA33: x | AB33: x | AK33: x
A34: DEV.2024.031 | B34: 45404 | C34: QA | J34: x | K34: x | O34: Temperature monitoring | P34: x | V34: x | AB34: x | AK34: x | AN34: x
A35: DEV.2024.032 | B35: 45412 | C35: QC | I35: x | O35: Equipment validation | AF35: x | AH35: Equipment | AL35: x
A36: DEV.2024.033 | B36: 45413 | C36: QC | L36: x | O36: Equipment | W36: x | AH36: Environmental factors | AM36: x
A37: DEV.2024.034 | B37: 45414 | C37: Production | H37: x | O37: Product manufacturing | R37: x
A38: DEV.2024.035 | B38: 45421 | C38: QC | L38: x | O38: QC testing | V38: x | AM38: x
A39: DEV.2024.036 | B39: 45426 | C39: Dispatch | J39: x | O39: Dispatch cleaning procedure | AA39: x | AN39: x
A40: DEV.2024.037 | B40: 45426 | C40: Production | I40: x | O40: Equipment validation | P40: x | AL40: x
...

Sheet Deviation Root Cause Trending
A1: Date Today: | B1: =TODAY() -> 46269
A2: Deviation Area | B2: Human Error | C2: Formulation Issue | D2: Material / Consumables Availability | E2: Inadequate Material / Consumables | F2: Communication Issue | G2: Inadequate Planning | H2: Procedure Is Defficient | I2: Equipment Fault - Wear And Tear | J2: Inadequate Storage | K2: No Procedure In Place | L2: Equipment Availability | M2: Training / Skills / Knowledge Issue | N2: Staff Availability | O2: IT/System Issues | P2: Facility Issue | Q2: Environmental Conditions | R2: Validation /Calibration | S2: Gdocp Not Followed | T2: Other
A3: QC Testing | B3: =_xlfn.LET( _xlpm.result, COUNTIFS( 'Deviation RC Data'!$O:$O, $A3, 'Deviation RC Data'!P:P, "x", 'Deviation RC Data'!$B:$B, ">=" & EDATE($B$1, -12), 'Deviation RC Data'!$B:$B, "<=" & $B$1 ), IF(_xlpm.result = 0, "", _xlpm.result) ) | C3: =_xlfn.LET( _xlpm.result, COUNTIFS( 'Deviation RC Data'!$O:$O, $A3, 'Deviation RC Data'!Q:Q, "x", 'Deviation RC Data'!$B:$B, ">=" & EDATE($B$1, -12), 'Deviation RC Data'!$B:$B, "<=" & $B$1 ), IF(_xlpm.result = 0, "", _xlpm.result) ) | D3: =_xlfn.LET( _xlpm.result, COUNTIFS( 'Deviation RC Data'!$O:$O, $A3, 'Deviation RC Data'!R:R, "x", 'Deviation RC Data'!$B:$B, ">=" & EDATE($B$1, -12), 'Deviation RC Data'!$B:$B, "<=" & $B$1 ), IF(_xlpm.result = 0, "", _xlpm.result) ) | E3: =_xlfn.LET( _xlpm.result, COUNTIFS( 'Deviation RC Data'!$O:$O, $A3, 'Deviation RC Data'!S:S, "x", 'Deviation RC Data'!$B:$B, ">=" & EDATE($B$1, -12), 'Deviation RC Data'!$B:$B, "<=" & $B$1 ), IF(_xlpm.result = 0, "", _xlpm.result) ) | F3: =_xlfn.LET( _xlpm.result, COUNTIFS( 'Deviation RC Data'!$O:$O, $A3, 'Deviation RC Data'!T:T, "x", 'Deviation RC Data'!$B:$B, ">=" & EDATE($B$1, -12), 'Deviation RC Data'!$B:$B, "<=" & $B$1 ), IF(_xlpm.result = 0, "", _xlpm.result) ) | G3: =_xlfn.LET( _xlpm.result, COUNTIFS( 'Deviation RC Data'!$O:$O, $A3, 'Deviation RC Data'!U:U, "x", 'Deviation RC Data'!$B:$B, ">=" & EDATE($B$1, -12), 'Deviation RC Data'!$B:$B, "<=" & $B$1 ), IF(_xlpm.result = 0, "", _xlpm.result) ) | H3: =_xlfn.LET( _xlpm.result, COUNTIFS( 'Deviation RC Data'!$O:$O, $A3, 'Deviation RC Data'!V:V, "x", 'Deviation RC Data'!$B:$B, ">=" & EDATE($B$1, -12), 'Deviation RC Data'!$B:$B, "<=" & $B$1 ), IF(_xlpm.result = 0, "", _xlpm.result) ) -> 1 | I3: =_xlfn.LET( _xlpm.result, COUNTIFS( 'Deviation RC Data'!$O:$O, $A3, 'Deviation RC Data'!W:W, "x", 'Deviation RC Data'!$B:$B, ">=" & EDATE($B$1, -12), 'Deviation RC Data'!$B:$B, "<=" & $B$1 ), IF(_xlpm.result = 0, "", _xlpm.result) ) -> 2 | J3: =_xlfn.LET( _xlpm.result, COUNTIFS( 'Deviation RC Data'!$O:$O, $A3, 'Deviation RC Data'!X:X, "x", 'Deviation RC Data'!$B:$B, ">=" & EDATE($B$1, -12), 'Deviation RC Data'!$B:$B, "<=" & $B$1 ), IF(_xlpm.result = 0, "", _xlpm.result) ) | K3: =_xlfn.LET( _xlpm.result, COUNTIFS( 'Deviation RC Data'!$O:$O, $A3, 'Deviation RC Data'!Y:Y, "x", 'Deviation RC Data'!$B:$B, ">=" & EDATE($B$1, -12), 'Deviation RC Data'!$B:$B, "<=" & $B$1 ), IF(_xlpm.result = 0, "", _xlpm.result) ) | L3: =_xlfn.LET( _xlpm.result, COUNTIFS( 'Deviation RC Data'!$O:$O, $A3, 'Deviation RC Data'!Z:Z, "x", 'Deviation RC Data'!$B:$B, ">=" & EDATE($B$1, -12), 'Deviation RC Data'!$B:$B, "<=" & $B$1 ), IF(_xlpm.result = 0, "", _xlpm.result) ) | M3: =_xlfn.LET( _xlpm.result, COUNTIFS( 'Deviation RC Data'!$O:$O, $A3, 'Deviation RC Data'!AA:AA, "x", 'Deviation RC Data'!$B:$B, ">=" & EDATE($B$1, -12), 'Deviation RC Data'!$B:$B, "<=" & $B$1 ), IF(_xlpm.result = 0, "", _xlpm.result) ) | N3: =_xlfn.LET( _xlpm.result, COUNTIFS( 'Deviation RC Data'!$O:$O, $A3, 'Deviation RC Data'!AB:AB, "x", 'Deviation RC Data'!$B:$B, ">=" & EDATE($B$1, -12), 'Deviation RC Data'!$B:$B, "<=" & $B$1 ), IF(_xlpm.result = 0, "", _xlpm.result) ) | O3: =_xlfn.LET( _xlpm.result, COUNTIFS( 'Deviation RC Data'!$O:$O, $A3, 'Deviation RC Data'!AC:AC, "x", 'Deviation RC Data'!$B:$B, ">=" & EDATE($B$1, -12), 'Deviation RC Data'!$B:$B, "<=" & $B$1 ), IF(_xlpm.result = 0, "", _xlpm.result) ) | P3: =_xlfn.LET( _xlpm.result, COUNTIFS( 'Deviation RC Data'!$O:$O, $A3, 'Deviation RC Data'!AD:AD, "x", 'Deviation RC Data'!$B:$B, ">=" & EDATE($B$1, -12), 'Deviation RC Data'!$B:$B, "<=" & $B$1 ), IF(_xlpm.result = 0, "", _xlpm.result) ) | Q3: =_xlfn.LET( _xlpm.result, COUNTIFS( 'Deviation RC Data'!$O:$O, $A3, 'Deviation RC Data'!AE:AE, "x", 'Deviation RC Data'!$B:$B, ">=" & EDATE($B$1, -12), 'Deviation RC Data'!$B:$B, "<=" & $B$1 ), IF(_xlpm.result = 0, "", _xlpm.result) ) | R3: =_xlfn.LET( _xlpm.result, COUNTIFS( 'Deviation RC Data'!$O:$O, $A3, 'Deviation RC Data'!AF:AF, "x", 'Deviation RC Data'!$B:$B, ">=" & EDATE($B$1, -12), 'Deviation RC Data'!$B:$B, "<=" & $B$1 ), IF(_xlpm.result = 0, "", _xlpm.result) ) | S3: =_xlfn.LET( _xlpm.result, COUNTIFS( 'Deviation RC Data'!$O:$O, $A3, 'Deviation RC Data'!AG:AG, "x", 'Deviation RC Data'!$B:$B, ">=" & EDATE($B$1, -12), 'Deviation RC Data'!$B:$B, "<=" & $B$1 ), IF(_xlpm.result = 0, "", _xlpm.result) ) | T3: =_xlfn.LET( _xlpm.result, COUNTIFS( 'Deviation RC Data'!$O:$O, $A3, 'Deviation RC Data'!AH:AH, "x", 'Deviation RC Data'!$B:$B, ">=" & EDATE($B$1, -12), 'Deviation RC Data'!$B:$B, "<=" & $B$1 ), IF(_xlpm.result = 0, "", _xlpm.result) )
A4: QC Samples | B4: =_xlfn.LET( _xlpm.result, COUNTIFS( 'Deviation RC Data'!$O:$O, $A4, 'Deviation RC Data'!P:P, "x", 'Deviation RC Data'!$B:$B, ">=" & EDATE($B$1, -12), 'Deviation RC Data'!$B:$B, "<=" & $B$1 ), IF(_xlpm.result = 0, "", _xlpm.result) ) | C4: =_xlfn.LET( _xlpm.result, COUNTIFS( 'Deviation RC Data'!$O:$O, $A4, 'Deviation RC Data'!Q:Q, "x", 'Deviation RC Data'!$B:$B, ">=" & EDATE($B$1, -12), 'Deviation RC Data'!$B:$B, "<=" & $B$1 ), IF(_xlpm.result = 0, "", _xlpm.result) ) | D4: =_xlfn.LET( _xlpm.result, COUNTIFS( 'Deviation RC Data'!$O:$O, $A4, 'Deviation RC Data'!R:R, "x", 'Deviation RC Data'!$B:$B, ">=" & EDATE($B$1, -12), 'Deviation RC Data'!$B:$B, "<=" & $B$1 ), IF(_xlpm.result = 0, "", _xlpm.result) ) | E4: =_xlfn.LET( _xlpm.result, COUNTIFS( 'Deviation RC Data'!$O:$O, $A4, 'Deviation RC Data'!S:S, "x", 'Deviation RC Data'!$B:$B, ">=" & EDATE($B$1, -12), 'Deviation RC Data'!$B:$B, "<=" & $B$1 ), IF(_xlpm.result = 0, "", _xlpm.result) ) | F4: =_xlfn.LET( _xlpm.result, COUNTIFS( 'Deviation RC Data'!$O:$O, $A4, 'Deviation RC Data'!T:T, "x", 'Deviation RC Data'!$B:$B, ">=" & EDATE($B$1, -12), 'Deviation RC Data'!$B:$B, "<=" & $B$1 ), IF(_xlpm.result = 0, "", _xlpm.result) ) | G4: =_xlfn.LET( _xlpm.result, COUNTIFS( 'Deviation RC Data'!$O:$O, $A4, 'Deviation RC Data'!U:U, "x", 'Deviation RC Data'!$B:$B, ">=" & EDATE($B$1, -12), 'Deviation RC Data'!$B:$B, "<=" & $B$1 ), IF(_xlpm.result = 0, "", _xlpm.result) ) | H4: =_xlfn.LET( _xlpm.result, COUNTIFS( 'Deviation RC Data'!$O:$O, $A4, 'Deviation RC Data'!V:V, "x", 'Deviation RC Data'!$B:$B, ">=" & EDATE($B$1, -12), 'Deviation RC Data'!$B:$B, "<=" & $B$1 ), IF(_xlpm.result = 0, "", _xlpm.result) ) | I4: =_xlfn.LET( _xlpm.result, COUNTIFS( 'Deviation RC Data'!$O:$O, $A4, 'Deviation RC Data'!W:W, "x", 'Deviation RC Data'!$B:$B, ">=" & EDATE($B$1, -12), 'Deviation RC Data'!$B:$B, "<=" & $B$1 ), IF(_xlpm.result = 0, "", _xlpm.result) ) -> 1 | J4: =_xlfn.LET( _xlpm.result, COUNTIFS( 'Deviation RC Data'!$O:$O, $A4, 'Deviation RC Data'!X:X, "x", 'Deviation RC Data'!$B:$B, ">=" & EDATE($B$1, -12), 'Deviation RC Data'!$B:$B, "<=" & $B$1 ), IF(_xlpm.result = 0, "", _xlpm.result) ) | K4: =_xlfn.LET( _xlpm.result, COUNTIFS( 'Deviation RC Data'!$O:$O, $A4, 'Deviation RC Data'!Y:Y, "x", 'Deviation RC Data'!$B:$B, ">=" & EDATE($B$1, -12), 'Deviation RC Data'!$B:$B, "<=" & $B$1 ), IF(_xlpm.result = 0, "", _xlpm.result) ) | L4: =_xlfn.LET( _xlpm.result, COUNTIFS( 'Deviation RC Data'!$O:$O, $A4, 'Deviation RC Data'!Z:Z, "x", 'Deviation RC Data'!$B:$B, ">=" & EDATE($B$1, -12), 'Deviation RC Data'!$B:$B, "<=" & $B$1 ), IF(_xlpm.result = 0, "", _xlpm.result) ) | M4: =_xlfn.LET( _xlpm.result, COUNTIFS( 'Deviation RC Data'!$O:$O, $A4, 'Deviation RC Data'!AA:AA, "x", 'Deviation RC Data'!$B:$B, ">=" & EDATE($B$1, -12), 'Deviation RC Data'!$B:$B, "<=" & $B$1 ), IF(_xlpm.result = 0, "", _xlpm.result) ) | N4: =_xlfn.LET( _xlpm.result, COUNTIFS( 'Deviation RC Data'!$O:$O, $A4, 'Deviation RC Data'!AB:AB, "x", 'Deviation RC Data'!$B:$B, ">=" & EDATE($B$1, -12), 'Deviation RC Data'!$B:$B, "<=" & $B$1 ), IF(_xlpm.result = 0, "", _xlpm.result) ) | O4: =_xlfn.LET( _xlpm.result, COUNTIFS( 'Deviation RC Data'!$O:$O, $A4, 'Deviation RC Data'!AC:AC, "x", 'Deviation RC Data'!$B:$B, ">=" & EDATE($B$1, -12), 'Deviation RC Data'!$B:$B, "<=" & $B$1 ), IF(_xlpm.result = 0, "", _xlpm.result) ) | P4: =_xlfn.LET( _xlpm.result, COUNTIFS( 'Deviation RC Data'!$O:$O, $A4, 'Deviation RC Data'!AD:AD, "x", 'Deviation RC Data'!$B:$B, ">=" & EDATE($B$1, -12), 'Deviation RC Data'!$B:$B, "<=" & $B$1 ), IF(_xlpm.result = 0, "", _xlpm.result) ) | Q4: =_xlfn.LET( _xlpm.result, COUNTIFS( 'Deviation RC Data'!$O:$O, $A4, 'Deviation RC Data'!AE:AE, "x", 'Deviation RC Data'!$B:$B, ">=" & EDATE($B$1, -12), 'Deviation RC Data'!$B:$B, "<=" & $B$1 ), IF(_xlpm.result = 0, "", _xlpm.result) ) | R4: =_xlfn.LET( _xlpm.result, COUNTIFS( 'Deviation RC Data'!$O:$O, $A4, 'Deviation RC Data'!AF:AF, "x", 'Deviation RC Data'!$B:$B, ">=" & EDATE($B$1, -12), 'Deviation RC Data'!$B:$B, "<=" & $B$1 ), IF(_xlpm.result = 0, "", _xlpm.result) ) | S4: =_xlfn.LET( _xlpm.result, COUNTIFS( 'Deviation RC Data'!$O:$O, $A4, 'Deviation RC Data'!AG:AG, "x", 'Deviation RC Data'!$B:$B, ">=" & EDATE($B$1, -12), 'Deviation RC Data'!$B:$B, "<=" & $B$1 ), IF(_xlpm.result = 0, "", _xlpm.result) ) | T4: =_xlfn.LET( _xlpm.result, COUNTIFS( 'Deviation RC Data'!$O:$O, $A4, 'Deviation RC Data'!AH:AH, "x", 'Deviation RC Data'!$B:$B, ">=" & EDATE($B$1, -12), 'Deviation RC Data'!$B:$B, "<=" & $B$1 ), IF(_xlpm.result = 0, "", _xlpm.result) ) -> 1
A5: QC Annual Performance Qualification | B5: =_xlfn.LET( _xlpm.result, COUNTIFS( 'Deviation RC Data'!$O:$O, $A5, 'Deviation RC Data'!P:P, "x", 'Deviation RC Data'!$B:$B, ">=" & EDATE($B$1, -12), 'Deviation RC Data'!$B:$B, "<=" & $B$1 ), IF(_xlpm.result = 0, "", _xlpm.result) ) | C5: =_xlfn.LET( _xlpm.result, COUNTIFS( 'Deviation RC Data'!$O:$O, $A5, 'Deviation RC Data'!Q:Q, "x", 'Deviation RC Data'!$B:$B, ">=" & EDATE($B$1, -12), 'Deviation RC Data'!$B:$B, "<=" & $B$1 ), IF(_xlpm.result = 0, "", _xlpm.result) ) | D5: =_xlfn.LET( _xlpm.result, COUNTIFS( 'Deviation RC Data'!$O:$O, $A5, 'Deviation RC Data'!R:R, "x", 'Deviation RC Data'!$B:$B, ">=" & EDATE($B$1, -12), 'Deviation RC Data'!$B:$B, "<=" & $B$1 ), IF(_xlpm.result = 0, "", _xlpm.result) ) | E5: =_xlfn.LET( _xlpm.result, COUNTIFS( 'Deviation RC Data'!$O:$O, $A5, 'Deviation RC Data'!S:S, "x", 'Deviation RC Data'!$B:$B, ">=" & EDATE($B$1, -12), 'Deviation RC Data'!$B:$B, "<=" & $B$1 ), IF(_xlpm.result = 0, "", _xlpm.result) ) | F5: =_xlfn.LET( _xlpm.result, COUNTIFS( 'Deviation RC Data'!$O:$O, $A5, 'Deviation RC Data'!T:T, "x", 'Deviation RC Data'!$B:$B, ">=" & EDATE($B$1, -12), 'Deviation RC Data'!$B:$B, "<=" & $B$1 ), IF(_xlpm.result = 0, "", _xlpm.result) ) | G5: =_xlfn.LET( _xlpm.result, COUNTIFS( 'Deviation RC Data'!$O:$O, $A5, 'Deviation RC Data'!U:U, "x", 'Deviation RC Data'!$B:$B, ">=" & EDATE($B$1, -12), 'Deviation RC Data'!$B:$B, "<=" & $B$1 ), IF(_xlpm.result = 0, "", _xlpm.result) ) | H5: =_xlfn.LET( _xlpm.result, COUNTIFS( 'Deviation RC Data'!$O:$O, $A5, 'Deviation RC Data'!V:V, "x", 'Deviation RC Data'!$B:$B, ">=" & EDATE($B$1, -12), 'Deviation RC Data'!$B:$B, "<=" & $B$1 ), IF(_xlpm.result = 0, "", _xlpm.result) ) | I5: =_xlfn.LET( _xlpm.result, COUNTIFS( 'Deviation RC Data'!$O:$O, $A5, 'Deviation RC Data'!W:W, "x", 'Deviation RC Data'!$B:$B, ">=" & EDATE($B$1, -12), 'Deviation RC Data'!$B:$B, "<=" & $B$1 ), IF(_xlpm.result = 0, "", _xlpm.result) ) | J5: =_xlfn.LET( _xlpm.result, COUNTIFS( 'Deviation RC Data'!$O:$O, $A5, 'Deviation RC Data'!X:X, "x", 'Deviation RC Data'!$B:$B, ">=" & EDATE($B$1, -12), 'Deviation RC Data'!$B:$B, "<=" & $B$1 ), IF(_xlpm.result = 0, "", _xlpm.result) ) | K5: =_xlfn.LET( _xlpm.result, COUNTIFS( 'Deviation RC Data'!$O:$O, $A5, 'Deviation RC Data'!Y:Y, "x", 'Deviation RC Data'!$B:$B, ">=" & EDATE($B$1, -12), 'Deviation RC Data'!$B:$B, "<=" & $B$1 ), IF(_xlpm.result = 0, "", _xlpm.result) ) | L5: =_xlfn.LET( _xlpm.result, COUNTIFS( 'Deviation RC Data'!$O:$O, $A5, 'Deviation RC Data'!Z:Z, "x", 'Deviation RC Data'!$B:$B, ">=" & EDATE($B$1, -12), 'Deviation RC Data'!$B:$B, "<=" & $B$1 ), IF(_xlpm.result = 0, "", _xlpm.result) ) | M5: =_xlfn.LET( _xlpm.result, COUNTIFS( 'Deviation RC Data'!$O:$O, $A5, 'Deviation RC Data'!AA:AA, "x", 'Deviation RC Data'!$B:$B, ">=" & EDATE($B$1, -12), 'Deviation RC Data'!$B:$B, "<=" & $B$1 ), IF(_xlpm.result = 0, "", _xlpm.result) ) | N5: =_xlfn.LET( _xlpm.result, COUNTIFS( 'Deviation RC Data'!$O:$O, $A5, 'Deviation RC Data'!AB:AB, "x", 'Deviation RC Data'!$B:$B, ">=" & EDATE($B$1, -12), 'Deviation RC Data'!$B:$B, "<=" & $B$1 ), IF(_xlpm.result = 0, "", _xlpm.result) ) | O5: =_xlfn.LET( _xlpm.result, COUNTIFS( 'Deviation RC Data'!$O:$O, $A5, 'Deviation RC Data'!AC:AC, "x", 'Deviation RC Data'!$B:$B, ">=" & EDATE($B$1, -12), 'Deviation RC Data'!$B:$B, "<=" & $B$1 ), IF(_xlpm.result = 0, "", _xlpm.result) ) | P5: =_xlfn.LET( _xlpm.result, COUNTIFS( 'Deviation RC Data'!$O:$O, $A5, 'Deviation RC Data'!AD:AD, "x", 'Deviation RC Data'!$B:$B, ">=" & EDATE($B$1, -12), 'Deviation RC Data'!$B:$B, "<=" & $B$1 ), IF(_xlpm.result = 0, "", _xlpm.result) ) | Q5: =_xlfn.LET( _xlpm.result, COUNTIFS( 'Deviation RC Data'!$O:$O, $A5, 'Deviation RC Data'!AE:AE, "x", 'Deviation RC Data'!$B:$B, ">=" & EDATE($B$1, -12), 'Deviation RC Data'!$B:$B, "<=" & $B$1 ), IF(_xlpm.result = 0, "", _xlpm.result) ) | R5: =_xlfn.LET( _xlpm.result, COUNTIFS( 'Deviation RC Data'!$O:$O, $A5, 'Deviation RC Data'!AF:AF, "x", 'Deviation RC Data'!$B:$B, ">=" & EDATE($B$1, -12), 'Deviation RC Data'!$B:$B, "<=" & $B$1 ), IF(_xlpm.result = 0, "", _xlpm.result) ) | S5: =_xlfn.LET( _xlpm.result, COUNTIFS( 'Deviation RC Data'!$O:$O, $A5, 'Deviation RC Data'!AG:AG, "x", 'Deviation RC Data'!$B:$B, ">=" & EDATE($B$1, -12), 'Deviation RC Data'!$B:$B, "<=" & $B$1 ), IF(_xlpm.result = 0, "", _xlpm.result) ) | T5: =_xlfn.LET( _xlpm.result, COUNTIFS( 'Deviation RC Data'!$O:$O, $A5, 'Deviation RC Data'!AH:AH, "x", 'Deviation RC Data'!$B:$B, ">=" & EDATE($B$1, -12), 'Deviation RC Data'!$B:$B, "<=" & $B$1 ), IF(_xlpm.result = 0, "", _xlpm.result) )
A6: QC Standards | B6: =_xlfn.LET( _xlpm.result, COUNTIFS( 'Deviation RC Data'!$O:$O, $A6, 'Deviation RC Data'!P:P, "x", 'Deviation RC Data'!$B:$B, ">=" & EDATE($B$1, -12), 'Deviation RC Data'!$B:$B, "<=" & $B$1 ), IF(_xlpm.result = 0, "", _xlpm.result) ) | C6: =_xlfn.LET( _xlpm.result, COUNTIFS( 'Deviation RC Data'!$O:$O, $A6, 'Deviation RC Data'!Q:Q, "x", 'Deviation RC Data'!$B:$B, ">=" & EDATE($B$1, -12), 'Deviation RC Data'!$B:$B, "<=" & $B$1 ), IF(_xlpm.result = 0, "", _xlpm.result) ) | D6: =_xlfn.LET( _xlpm.result, COUNTIFS( 'Deviation RC Data'!$O:$O, $A6, 'Deviation RC Data'!R:R, "x", 'Deviation RC Data'!$B:$B, ">=" & EDATE($B$1, -12), 'Deviation RC Data'!$B:$B, "<=" & $B$1 ), IF(_xlpm.result = 0, "", _xlpm.result) ) | E6: =_xlfn.LET( _xlpm.result, COUNTIFS( 'Deviation RC Data'!$O:$O, $A6, 'Deviation RC Data'!S:S, "x", 'Deviation RC Data'!$B:$B, ">=" & EDATE($B$1, -12), 'Deviation RC Data'!$B:$B, "<=" & $B$1 ), IF(_xlpm.result = 0, "", _xlpm.result) ) | F6: =_xlfn.LET( _xlpm.result, COUNTIFS( 'Deviation RC Data'!$O:$O, $A6, 'Deviation RC Data'!T:T, "x", 'Deviation RC Data'!$B:$B, ">=" & EDATE($B$1, -12), 'Deviation RC Data'!$B:$B, "<=" & $B$1 ), IF(_xlpm.result = 0, "", _xlpm.result) ) | G6: =_xlfn.LET( _xlpm.result, COUNTIFS( 'Deviation RC Data'!$O:$O, $A6, 'Deviation RC Data'!U:U, "x", 'Deviation RC Data'!$B:$B, ">=" & EDATE($B$1, -12), 'Deviation RC Data'!$B:$B, "<=" & $B$1 ), IF(_xlpm.result = 0, "", _xlpm.result) ) | H6: =_xlfn.LET( _xlpm.result, COUNTIFS( 'Deviation RC Data'!$O:$O, $A6, 'Deviation RC Data'!V:V, "x", 'Deviation RC Data'!$B:$B, ">=" & EDATE($B$1, -12), 'Deviation RC Data'!$B:$B, "<=" & $B$1 ), IF(_xlpm.result = 0, "", _xlpm.result) ) | I6: =_xlfn.LET( _xlpm.result, COUNTIFS( 'Deviation RC Data'!$O:$O, $A6, 'Deviation RC Data'!W:W, "x", 'Deviation RC Data'!$B:$B, ">=" & EDATE($B$1, -12), 'Deviation RC Data'!$B:$B, "<=" & $B$1 ), IF(_xlpm.result = 0, "", _xlpm.result) ) | J6: =_xlfn.LET( _xlpm.result, COUNTIFS( 'Deviation RC Data'!$O:$O, $A6, 'Deviation RC Data'!X:X, "x", 'Deviation RC Data'!$B:$B, ">=" & EDATE($B$1, -12), 'Deviation RC Data'!$B:$B, "<=" & $B$1 ), IF(_xlpm.result = 0, "", _xlpm.result) ) | K6: =_xlfn.LET( _xlpm.result, COUNTIFS( 'Deviation RC Data'!$O:$O, $A6, 'Deviation RC Data'!Y:Y, "x", 'Deviation RC Data'!$B:$B, ">=" & EDATE($B$1, -12), 'Deviation RC Data'!$B:$B, "<=" & $B$1 ), IF(_xlpm.result = 0, "", _xlpm.result) ) | L6: =_xlfn.LET( _xlpm.result, COUNTIFS( 'Deviation RC Data'!$O:$O, $A6, 'Deviation RC Data'!Z:Z, "x", 'Deviation RC Data'!$B:$B, ">=" & EDATE($B$1, -12), 'Deviation RC Data'!$B:$B, "<=" & $B$1 ), IF(_xlpm.result = 0, "", _xlpm.result) ) | M6: =_xlfn.LET( _xlpm.result, COUNTIFS( 'Deviation RC Data'!$O:$O, $A6, 'Deviation RC Data'!AA:AA, "x", 'Deviation RC Data'!$B:$B, ">=" & EDATE($B$1, -12), 'Deviation RC Data'!$B:$B, "<=" & $B$1 ), IF(_xlpm.result = 0, "", _xlpm.result) ) | N6: =_xlfn.LET( _xlpm.result, COUNTIFS( 'Deviation RC Data'!$O:$O, $A6, 'Deviation RC Data'!AB:AB, "x", 'Deviation RC Data'!$B:$B, ">=" & EDATE($B$1, -12), 'Deviation RC Data'!$B:$B, "<=" & $B$1 ), IF(_xlpm.result = 0, "", _xlpm.result) ) | O6: =_xlfn.LET( _xlpm.result, COUNTIFS( 'Deviation RC Data'!$O:$O, $A6, 'Deviation RC Data'!AC:AC, "x", 'Deviation RC Data'!$B:$B, ">=" & EDATE($B$1, -12), 'Deviation RC Data'!$B:$B, "<=" & $B$1 ), IF(_xlpm.result = 0, "", _xlpm.result) ) | P6: =_xlfn.LET( _xlpm.result, COUNTIFS( 'Deviation RC Data'!$O:$O, $A6, 'Deviation RC Data'!AD:AD, "x", 'Deviation RC Data'!$B:$B, ">=" & EDATE($B$1, -12), 'Deviation RC Data'!$B:$B, "<=" & $B$1 ), IF(_xlpm.result = 0, "", _xlpm.result) ) | Q6: =_xlfn.LET( _xlpm.result, COUNTIFS( 'Deviation RC Data'!$O:$O, $A6, 'Deviation RC Data'!AE:AE, "x", 'Deviation RC Data'!$B:$B, ">=" & EDATE($B$1, -12), 'Deviation RC Data'!$B:$B, "<=" & $B$1 ), IF(_xlpm.result = 0, "", _xlpm.result) ) | R6: =_xlfn.LET( _xlpm.result, COUNTIFS( 'Deviation RC Data'!$O:$O, $A6, 'Deviation RC Data'!AF:AF, "x", 'Deviation RC Data'!$B:$B, ">=" & EDATE($B$1, -12), 'Deviation RC Data'!$B:$B, "<=" & $B$1 ), IF(_xlpm.result = 0, "", _xlpm.result) ) | S6: =_xlfn.LET( _xlpm.result, COUNTIFS( 'Deviation RC Data'!$O:$O, $A6, 'Deviation RC Data'!AG:AG, "x", 'Deviation RC Data'!$B:$B, ">=" & EDATE($B$1, -12), 'Deviation RC Data'!$B:$B, "<=" & $B$1 ), IF(_xlpm.result = 0, "", _xlpm.result) ) | T6: =_xlfn.LET( _xlpm.result, COUNTIFS( 'Deviation RC Data'!$O:$O, $A6, 'Deviation RC Data'!AH:AH, "x", 'Deviation RC Data'!$B:$B, ">=" & EDATE($B$1, -12), 'Deviation RC Data'!$B:$B, "<=" & $B$1 ), IF(_xlpm.result = 0, "", _xlpm.result) )
A7: Internal Audits | B7: =_xlfn.LET( _xlpm.result, COUNTIFS( 'Deviation RC Data'!$O:$O, $A7, 'Deviation RC Data'!P:P, "x", 'Deviation RC Data'!$B:$B, ">=" & EDATE($B$1, -12), 'Deviation RC Data'!$B:$B, "<=" & $B$1 ), IF(_xlpm.result = 0, "", _xlpm.result) ) | C7: =_xlfn.LET( _xlpm.result, COUNTIFS( 'Deviation RC Data'!$O:$O, $A7, 'Deviation RC Data'!Q:Q, "x", 'Deviation RC Data'!$B:$B, ">=" & EDATE($B$1, -12), 'Deviation RC Data'!$B:$B, "<=" & $B$1 ), IF(_xlpm.result = 0, "", _xlpm.result) ) | D7: =_xlfn.LET( _xlpm.result, COUNTIFS( 'Deviation RC Data'!$O:$O, $A7, 'Deviation RC Data'!R:R, "x", 'Deviation RC Data'!$B:$B, ">=" & EDATE($B$1, -12), 'Deviation RC Data'!$B:$B, "<=" & $B$1 ), IF(_xlpm.result = 0, "", _xlpm.result) ) | E7: =_xlfn.LET( _xlpm.result, COUNTIFS( 'Deviation RC Data'!$O:$O, $A7, 'Deviation RC Data'!S:S, "x", 'Deviation RC Data'!$B:$B, ">=" & EDATE($B$1, -12), 'Deviation RC Data'!$B:$B, "<=" & $B$1 ), IF(_xlpm.result = 0, "", _xlpm.result) ) | F7: =_xlfn.LET( _xlpm.result, COUNTIFS( 'Deviation RC Data'!$O:$O, $A7, 'Deviation RC Data'!T:T, "x", 'Deviation RC Data'!$B:$B, ">=" & EDATE($B$1, -12), 'Deviation RC Data'!$B:$B, "<=" & $B$1 ), IF(_xlpm.result = 0, "", _xlpm.result) ) | G7: =_xlfn.LET( _xlpm.result, COUNTIFS( 'Deviation RC Data'!$O:$O, $A7, 'Deviation RC Data'!U:U, "x", 'Deviation RC Data'!$B:$B, ">=" & EDATE($B$1, -12), 'Deviation RC Data'!$B:$B, "<=" & $B$1 ), IF(_xlpm.result = 0, "", _xlpm.result) ) | H7: =_xlfn.LET( _xlpm.result, COUNTIFS( 'Deviation RC Data'!$O:$O, $A7, 'Deviation RC Data'!V:V, "x", 'Deviation RC Data'!$B:$B, ">=" & EDATE($B$1, -12), 'Deviation RC Data'!$B:$B, "<=" & $B$1 ), IF(_xlpm.result = 0, "", _xlpm.result) ) | I7: =_xlfn.LET( _xlpm.result, COUNTIFS( 'Deviation RC Data'!$O:$O, $A7, 'Deviation RC Data'!W:W, "x", 'Deviation RC Data'!$B:$B, ">=" & EDATE($B$1, -12), 'Deviation RC Data'!$B:$B, "<=" & $B$1 ), IF(_xlpm.result = 0, "", _xlpm.result) ) | J7: =_xlfn.LET( _xlpm.result, COUNTIFS( 'Deviation RC Data'!$O:$O, $A7, 'Deviation RC Data'!X:X, "x", 'Deviation RC Data'!$B:$B, ">=" & EDATE($B$1, -12), 'Deviation RC Data'!$B:$B, "<=" & $B$1 ), IF(_xlpm.result = 0, "", _xlpm.result) ) | K7: =_xlfn.LET( _xlpm.result, COUNTIFS( 'Deviation RC Data'!$O:$O, $A7, 'Deviation RC Data'!Y:Y, "x", 'Deviation RC Data'!$B:$B, ">=" & EDATE($B$1, -12), 'Deviation RC Data'!$B:$B, "<=" & $B$1 ), IF(_xlpm.result = 0, "", _xlpm.result) ) | L7: =_xlfn.LET( _xlpm.result, COUNTIFS( 'Deviation RC Data'!$O:$O, $A7, 'Deviation RC Data'!Z:Z, "x", 'Deviation RC Data'!$B:$B, ">=" & EDATE($B$1, -12), 'Deviation RC Data'!$B:$B, "<=" & $B$1 ), IF(_xlpm.result = 0, "", _xlpm.result) ) | M7: =_xlfn.LET( _xlpm.result, COUNTIFS( 'Deviation RC Data'!$O:$O, $A7, 'Deviation RC Data'!AA:AA, "x", 'Deviation RC Data'!$B:$B, ">=" & EDATE($B$1, -12), 'Deviation RC Data'!$B:$B, "<=" & $B$1 ), IF(_xlpm.result = 0, "", _xlpm.result) ) | N7: =_xlfn.LET( _xlpm.result, COUNTIFS( 'Deviation RC Data'!$O:$O, $A7, 'Deviation RC Data'!AB:AB, "x", 'Deviation RC Data'!$B:$B, ">=" & EDATE($B$1, -12), 'Deviation RC Data'!$B:$B, "<=" & $B$1 ), IF(_xlpm.result = 0, "", _xlpm.result) ) | O7: =_xlfn.LET( _xlpm.result, COUNTIFS( 'Deviation RC Data'!$O:$O, $A7, 'Deviation RC Data'!AC:AC, "x", 'Deviation RC Data'!$B:$B, ">=" & EDATE($B$1, -12), 'Deviation RC Data'!$B:$B, "<=" & $B$1 ), IF(_xlpm.result = 0, "", _xlpm.result) ) | P7: =_xlfn.LET( _xlpm.result, COUNTIFS( 'Deviation RC Data'!$O:$O, $A7, 'Deviation RC Data'!AD:AD, "x", 'Deviation RC Data'!$B:$B, ">=" & EDATE($B$1, -12), 'Deviation RC Data'!$B:$B, "<=" & $B$1 ), IF(_xlpm.result = 0, "", _xlpm.result) ) | Q7: =_xlfn.LET( _xlpm.result, COUNTIFS( 'Deviation RC Data'!$O:$O, $A7, 'Deviation RC Data'!AE:AE, "x", 'Deviation RC Data'!$B:$B, ">=" & EDATE($B$1, -12), 'Deviation RC Data'!$B:$B, "<=" & $B$1 ), IF(_xlpm.result = 0, "", _xlpm.result) ) | R7: =_xlfn.LET( _xlpm.result, COUNTIFS( 'Deviation RC Data'!$O:$O, $A7, 'Deviation RC Data'!AF:AF, "x", 'Deviation RC Data'!$B:$B, ">=" & EDATE($B$1, -12), 'Deviation RC Data'!$B:$B, "<=" & $B$1 ), IF(_xlpm.result = 0, "", _xlpm.result) ) | S7: =_xlfn.LET( _xlpm.result, COUNTIFS( 'Deviation RC Data'!$O:$O, $A7, 'Deviation RC Data'!AG:AG, "x", 'Deviation RC Data'!$B:$B, ">=" & EDATE($B$1, -12), 'Deviation RC Data'!$B:$B, "<=" & $B$1 ), IF(_xlpm.result = 0, "", _xlpm.result) ) | T7: =_xlfn.LET( _xlpm.result, COUNTIFS( 'Deviation RC Data'!$O:$O, $A7, 'Deviation RC Data'!AH:AH, "x", 'Deviation RC Data'!$B:$B, ">=" & EDATE($B$1, -12), 'Deviation RC Data'!$B:$B, "<=" & $B$1 ), IF(_xlpm.result = 0, "", _xlpm.result) )
A8: Third Party Product Release | B8: =_xlfn.LET( _xlpm.result, COUNTIFS( 'Deviation RC Data'!$O:$O, $A8, 'Deviation RC Data'!P:P, "x", 'Deviation RC Data'!$B:$B, ">=" & EDATE($B$1, -12), 'Deviation RC Data'!$B:$B, "<=" & $B$1 ), IF(_xlpm.result = 0, "", _xlpm.result) ) | C8: =_xlfn.LET( _xlpm.result, COUNTIFS( 'Deviation RC Data'!$O:$O, $A8, 'Deviation RC Data'!Q:Q, "x", 'Deviation RC Data'!$B:$B, ">=" & EDATE($B$1, -12), 'Deviation RC Data'!$B:$B, "<=" & $B$1 ), IF(_xlpm.result = 0, "", _xlpm.result) ) | D8: =_xlfn.LET( _xlpm.result, COUNTIFS( 'Deviation RC Data'!$O:$O, $A8, 'Deviation RC Data'!R:R, "x", 'Deviation RC Data'!$B:$B, ">=" & EDATE($B$1, -12), 'Deviation RC Data'!$B:$B, "<=" & $B$1 ), IF(_xlpm.result = 0, "", _xlpm.result) ) | E8: =_xlfn.LET( _xlpm.result, COUNTIFS( 'Deviation RC Data'!$O:$O, $A8, 'Deviation RC Data'!S:S, "x", 'Deviation RC Data'!$B:$B, ">=" & EDATE($B$1, -12), 'Deviation RC Data'!$B:$B, "<=" & $B$1 ), IF(_xlpm.result = 0, "", _xlpm.result) ) | F8: =_xlfn.LET( _xlpm.result, COUNTIFS( 'Deviation RC Data'!$O:$O, $A8, 'Deviation RC Data'!T:T, "x", 'Deviation RC Data'!$B:$B, ">=" & EDATE($B$1, -12), 'Deviation RC Data'!$B:$B, "<=" & $B$1 ), IF(_xlpm.result = 0, "", _xlpm.result) ) | G8: =_xlfn.LET( _xlpm.result, COUNTIFS( 'Deviation RC Data'!$O:$O, $A8, 'Deviation RC Data'!U:U, "x", 'Deviation RC Data'!$B:$B, ">=" & EDATE($B$1, -12), 'Deviation RC Data'!$B:$B, "<=" & $B$1 ), IF(_xlpm.result = 0, "", _xlpm.result) ) | H8: =_xlfn.LET( _xlpm.result, COUNTIFS( 'Deviation RC Data'!$O:$O, $A8, 'Deviation RC Data'!V:V, "x", 'Deviation RC Data'!$B:$B, ">=" & EDATE($B$1, -12), 'Deviation RC Data'!$B:$B, "<=" & $B$1 ), IF(_xlpm.result = 0, "", _xlpm.result) ) | I8: =_xlfn.LET( _xlpm.result, COUNTIFS( 'Deviation RC Data'!$O:$O, $A8, 'Deviation RC Data'!W:W, "x", 'Deviation RC Data'!$B:$B, ">=" & EDATE($B$1, -12), 'Deviation RC Data'!$B:$B, "<=" & $B$1 ), IF(_xlpm.result = 0, "", _xlpm.result) ) | J8: =_xlfn.LET( _xlpm.result, COUNTIFS( 'Deviation RC Data'!$O:$O, $A8, 'Deviation RC Data'!X:X, "x", 'Deviation RC Data'!$B:$B, ">=" & EDATE($B$1, -12), 'Deviation RC Data'!$B:$B, "<=" & $B$1 ), IF(_xlpm.result = 0, "", _xlpm.result) ) | K8: =_xlfn.LET( _xlpm.result, COUNTIFS( 'Deviation RC Data'!$O:$O, $A8, 'Deviation RC Data'!Y:Y, "x", 'Deviation RC Data'!$B:$B, ">=" & EDATE($B$1, -12), 'Deviation RC Data'!$B:$B, "<=" & $B$1 ), IF(_xlpm.result = 0, "", _xlpm.result) ) | L8: =_xlfn.LET( _xlpm.result, COUNTIFS( 'Deviation RC Data'!$O:$O, $A8, 'Deviation RC Data'!Z:Z, "x", 'Deviation RC Data'!$B:$B, ">=" & EDATE($B$1, -12), 'Deviation RC Data'!$B:$B, "<=" & $B$1 ), IF(_xlpm.result = 0, "", _xlpm.result) ) | M8: =_xlfn.LET( _xlpm.result, COUNTIFS( 'Deviation RC Data'!$O:$O, $A8, 'Deviation RC Data'!AA:AA, "x", 'Deviation RC Data'!$B:$B, ">=" & EDATE($B$1, -12), 'Deviation RC Data'!$B:$B, "<=" & $B$1 ), IF(_xlpm.result = 0, "", _xlpm.result) ) | N8: =_xlfn.LET( _xlpm.result, COUNTIFS( 'Deviation RC Data'!$O:$O, $A8, 'Deviation RC Data'!AB:AB, "x", 'Deviation RC Data'!$B:$B, ">=" & EDATE($B$1, -12), 'Deviation RC Data'!$B:$B, "<=" & $B$1 ), IF(_xlpm.result = 0, "", _xlpm.result) ) | O8: =_xlfn.LET( _xlpm.result, COUNTIFS( 'Deviation RC Data'!$O:$O, $A8, 'Deviation RC Data'!AC:AC, "x", 'Deviation RC Data'!$B:$B, ">=" & EDATE($B$1, -12), 'Deviation RC Data'!$B:$B, "<=" & $B$1 ), IF(_xlpm.result = 0, "", _xlpm.result) ) | P8: =_xlfn.LET( _xlpm.result, COUNTIFS( 'Deviation RC Data'!$O:$O, $A8, 'Deviation RC Data'!AD:AD, "x", 'Deviation RC Data'!$B:$B, ">=" & EDATE($B$1, -12), 'Deviation RC Data'!$B:$B, "<=" & $B$1 ), IF(_xlpm.result = 0, "", _xlpm.result) ) | Q8: =_xlfn.LET( _xlpm.result, COUNTIFS( 'Deviation RC Data'!$O:$O, $A8, 'Deviation RC Data'!AE:AE, "x", 'Deviation RC Data'!$B:$B, ">=" & EDATE($B$1, -12), 'Deviation RC Data'!$B:$B, "<=" & $B$1 ), IF(_xlpm.result = 0, "", _xlpm.result) ) | R8: =_xlfn.LET( _xlpm.result, COUNTIFS( 'Deviation RC Data'!$O:$O, $A8, 'Deviation RC Data'!AF:AF, "x", 'Deviation RC Data'!$B:$B, ">=" & EDATE($B$1, -12), 'Deviation RC Data'!$B:$B, "<=" & $B$1 ), IF(_xlpm.result = 0, "", _xlpm.result) ) | S8: =_xlfn.LET( _xlpm.result, COUNTIFS( 'Deviation RC Data'!$O:$O, $A8, 'Deviation RC Data'!AG:AG, "x", 'Deviation RC Data'!$B:$B, ">=" & EDATE($B$1, -12), 'Deviation RC Data'!$B:$B, "<=" & $B$1 ), IF(_xlpm.result = 0, "", _xlpm.result) ) | T8: =_xlfn.LET( _xlpm.result, COUNTIFS( 'Deviation RC Data'!$O:$O, $A8, 'Deviation RC Data'!AH:AH, "x", 'Deviation RC Data'!$B:$B, ">=" & EDATE($B$1, -12), 'Deviation RC Data'!$B:$B, "<=" & $B$1 ), IF(_xlpm.result = 0, "", _xlpm.result) )
A9: Product Processing | B9: =_xlfn.LET( _xlpm.result, COUNTIFS( 'Deviation RC Data'!$O:$O, $A9, 'Deviation RC Data'!P:P, "x", 'Deviation RC Data'!$B:$B, ">=" & EDATE($B$1, -12), 'Deviation RC Data'!$B:$B, "<=" & $B$1 ), IF(_xlpm.result = 0, "", _xlpm.result) ) | C9: =_xlfn.LET( _xlpm.result, COUNTIFS( 'Deviation RC Data'!$O:$O, $A9, 'Deviation RC Data'!Q:Q, "x", 'Deviation RC Data'!$B:$B, ">=" & EDATE($B$1, -12), 'Deviation RC Data'!$B:$B, "<=" & $B$1 ), IF(_xlpm.result = 0, "", _xlpm.result) ) | D9: =_xlfn.LET( _xlpm.result, COUNTIFS( 'Deviation RC Data'!$O:$O, $A9, 'Deviation RC Data'!R:R, "x", 'Deviation RC Data'!$B:$B, ">=" & EDATE($B$1, -12), 'Deviation RC Data'!$B:$B, "<=" & $B$1 ), IF(_xlpm.result = 0, "", _xlpm.result) ) | E9: =_xlfn.LET( _xlpm.result, COUNTIFS( 'Deviation RC Data'!$O:$O, $A9, 'Deviation RC Data'!S:S, "x", 'Deviation RC Data'!$B:$B, ">=" & EDATE($B$1, -12), 'Deviation RC Data'!$B:$B, "<=" & $B$1 ), IF(_xlpm.result = 0, "", _xlpm.result) ) | F9: =_xlfn.LET( _xlpm.result, COUNTIFS( 'Deviation RC Data'!$O:$O, $A9, 'Deviation RC Data'!T:T, "x", 'Deviation RC Data'!$B:$B, ">=" & EDATE($B$1, -12), 'Deviation RC Data'!$B:$B, "<=" & $B$1 ), IF(_xlpm.result = 0, "", _xlpm.result) ) | G9: =_xlfn.LET( _xlpm.result, COUNTIFS( 'Deviation RC Data'!$O:$O, $A9, 'Deviation RC Data'!U:U, "x", 'Deviation RC Data'!$B:$B, ">=" & EDATE($B$1, -12), 'Deviation RC Data'!$B:$B, "<=" & $B$1 ), IF(_xlpm.result = 0, "", _xlpm.result) ) | H9: =_xlfn.LET( _xlpm.result, COUNTIFS( 'Deviation RC Data'!$O:$O, $A9, 'Deviation RC Data'!V:V, "x", 'Deviation RC Data'!$B:$B, ">=" & EDATE($B$1, -12), 'Deviation RC Data'!$B:$B, "<=" & $B$1 ), IF(_xlpm.result = 0, "", _xlpm.result) ) | I9: =_xlfn.LET( _xlpm.result, COUNTIFS( 'Deviation RC Data'!$O:$O, $A9, 'Deviation RC Data'!W:W, "x", 'Deviation RC Data'!$B:$B, ">=" & EDATE($B$1, -12), 'Deviation RC Data'!$B:$B, "<=" & $B$1 ), IF(_xlpm.result = 0, "", _xlpm.result) ) | J9: =_xlfn.LET( _xlpm.result, COUNTIFS( 'Deviation RC Data'!$O:$O, $A9, 'Deviation RC Data'!X:X, "x", 'Deviation RC Data'!$B:$B, ">=" & EDATE($B$1, -12), 'Deviation RC Data'!$B:$B, "<=" & $B$1 ), IF(_xlpm.result = 0, "", _xlpm.result) ) | K9: =_xlfn.LET( _xlpm.result, COUNTIFS( 'Deviation RC Data'!$O:$O, $A9, 'Deviation RC Data'!Y:Y, "x", 'Deviation RC Data'!$B:$B, ">=" & EDATE($B$1, -12), 'Deviation RC Data'!$B:$B, "<=" & $B$1 ), IF(_xlpm.result = 0, "", _xlpm.result) ) | L9: =_xlfn.LET( _xlpm.result, COUNTIFS( 'Deviation RC Data'!$O:$O, $A9, 'Deviation RC Data'!Z:Z, "x", 'Deviation RC Data'!$B:$B, ">=" & EDATE($B$1, -12), 'Deviation RC Data'!$B:$B, "<=" & $B$1 ), IF(_xlpm.result = 0, "", _xlpm.result) ) | M9: =_xlfn.LET( _xlpm.result, COUNTIFS( 'Deviation RC Data'!$O:$O, $A9, 'Deviation RC Data'!AA:AA, "x", 'Deviation RC Data'!$B:$B, ">=" & EDATE($B$1, -12), 'Deviation RC Data'!$B:$B, "<=" & $B$1 ), IF(_xlpm.result = 0, "", _xlpm.result) ) | N9: =_xlfn.LET( _xlpm.result, COUNTIFS( 'Deviation RC Data'!$O:$O, $A9, 'Deviation RC Data'!AB:AB, "x", 'Deviation RC Data'!$B:$B, ">=" & EDATE($B$1, -12), 'Deviation RC Data'!$B:$B, "<=" & $B$1 ), IF(_xlpm.result = 0, "", _xlpm.result) ) | O9: =_xlfn.LET( _xlpm.result, COUNTIFS( 'Deviation RC Data'!$O:$O, $A9, 'Deviation RC Data'!AC:AC, "x", 'Deviation RC Data'!$B:$B, ">=" & EDATE($B$1, -12), 'Deviation RC Data'!$B:$B, "<=" & $B$1 ), IF(_xlpm.result = 0, "", _xlpm.result) ) | P9: =_xlfn.LET( _xlpm.result, COUNTIFS( 'Deviation RC Data'!$O:$O, $A9, 'Deviation RC Data'!AD:AD, "x", 'Deviation RC Data'!$B:$B, ">=" & EDATE($B$1, -12), 'Deviation RC Data'!$B:$B, "<=" & $B$1 ), IF(_xlpm.result = 0, "", _xlpm.result) ) | Q9: =_xlfn.LET( _xlpm.result, COUNTIFS( 'Deviation RC Data'!$O:$O, $A9, 'Deviation RC Data'!AE:AE, "x", 'Deviation RC Data'!$B:$B, ">=" & EDATE($B$1, -12), 'Deviation RC Data'!$B:$B, "<=" & $B$1 ), IF(_xlpm.result = 0, "", _xlpm.result) ) | R9: =_xlfn.LET( _xlpm.result, COUNTIFS( 'Deviation RC Data'!$O:$O, $A9, 'Deviation RC Data'!AF:AF, "x", 'Deviation RC Data'!$B:$B, ">=" & EDATE($B$1, -12), 'Deviation RC Data'!$B:$B, "<=" & $B$1 ), IF(_xlpm.result = 0, "", _xlpm.result) ) | S9: =_xlfn.LET( _xlpm.result, COUNTIFS( 'Deviation RC Data'!$O:$O, $A9, 'Deviation RC Data'!AG:AG, "x", 'Deviation RC Data'!$B:$B, ">=" & EDATE($B$1, -12), 'Deviation RC Data'!$B:$B, "<=" & $B$1 ), IF(_xlpm.result = 0, "", _xlpm.result) ) | T9: =_xlfn.LET( _xlpm.result, COUNTIFS( 'Deviation RC Data'!$O:$O, $A9, 'Deviation RC Data'!AH:AH, "x", 'Deviation RC Data'!$B:$B, ">=" & EDATE($B$1, -12), 'Deviation RC Data'!$B:$B, "<=" & $B$1 ), IF(_xlpm.result = 0, "", _xlpm.result) )
A10: Product Manufacturing | B10: =_xlfn.LET( _xlpm.result, COUNTIFS( 'Deviation RC Data'!$O:$O, $A10, 'Deviation RC Data'!P:P, "x", 'Deviation RC Data'!$B:$B, ">=" & EDATE($B$1, -12), 'Deviation RC Data'!$B:$B, "<=" & $B$1 ), IF(_xlpm.result = 0, "", _xlpm.result) ) -> 3 | C10: =_xlfn.LET( _xlpm.result, COUNTIFS( 'Deviation RC Data'!$O:$O, $A10, 'Deviation RC Data'!Q:Q, "x", 'Deviation RC Data'!$B:$B, ">=" & EDATE($B$1, -12), 'Deviation RC Data'!$B:$B, "<=" & $B$1 ), IF(_xlpm.result = 0, "", _xlpm.result) ) -> 1 | D10: =_xlfn.LET( _xlpm.result, COUNTIFS( 'Deviation RC Data'!$O:$O, $A10, 'Deviation RC Data'!R:R, "x", 'Deviation RC Data'!$B:$B, ">=" & EDATE($B$1, -12), 'Deviation RC Data'!$B:$B, "<=" & $B$1 ), IF(_xlpm.result = 0, "", _xlpm.result) ) | E10: =_xlfn.LET( _xlpm.result, COUNTIFS( 'Deviation RC Data'!$O:$O, $A10, 'Deviation RC Data'!S:S, "x", 'Deviation RC Data'!$B:$B, ">=" & EDATE($B$1, -12), 'Deviation RC Data'!$B:$B, "<=" & $B$1 ), IF(_xlpm.result = 0, "", _xlpm.result) ) | F10: =_xlfn.LET( _xlpm.result, COUNTIFS( 'Deviation RC Data'!$O:$O, $A10, 'Deviation RC Data'!T:T, "x", 'Deviation RC Data'!$B:$B, ">=" & EDATE($B$1, -12), 'Deviation RC Data'!$B:$B, "<=" & $B$1 ), IF(_xlpm.result = 0, "", _xlpm.result) ) | G10: =_xlfn.LET( _xlpm.result, COUNTIFS( 'Deviation RC Data'!$O:$O, $A10, 'Deviation RC Data'!U:U, "x", 'Deviation RC Data'!$B:$B, ">=" & EDATE($B$1, -12), 'Deviation RC Data'!$B:$B, "<=" & $B$1 ), IF(_xlpm.result = 0, "", _xlpm.result) ) | H10: =_xlfn.LET( _xlpm.result, COUNTIFS( 'Deviation RC Data'!$O:$O, $A10, 'Deviation RC Data'!V:V, "x", 'Deviation RC Data'!$B:$B, ">=" & EDATE($B$1, -12), 'Deviation RC Data'!$B:$B, "<=" & $B$1 ), IF(_xlpm.result = 0, "", _xlpm.result) ) -> 4 | I10: =_xlfn.LET( _xlpm.result, COUNTIFS( 'Deviation RC Data'!$O:$O, $A10, 'Deviation RC Data'!W:W, "x", 'Deviation RC Data'!$B:$B, ">=" & EDATE($B$1, -12), 'Deviation RC Data'!$B:$B, "<=" & $B$1 ), IF(_xlpm.result = 0, "", _xlpm.result) ) | J10: =_xlfn.LET( _xlpm.result, COUNTIFS( 'Deviation RC Data'!$O:$O, $A10, 'Deviation RC Data'!X:X, "x", 'Deviation RC Data'!$B:$B, ">=" & EDATE($B$1, -12), 'Deviation RC Data'!$B:$B, "<=" & $B$1 ), IF(_xlpm.result = 0, "", _xlpm.result) ) | K10: =_xlfn.LET( _xlpm.result, COUNTIFS( 'Deviation RC Data'!$O:$O, $A10, 'Deviation RC Data'!Y:Y, "x", 'Deviation RC Data'!$B:$B, ">=" & EDATE($B$1, -12), 'Deviation RC Data'!$B:$B, "<=" & $B$1 ), IF(_xlpm.result = 0, "", _xlpm.result) ) -> 1 | L10: =_xlfn.LET( _xlpm.result, COUNTIFS( 'Deviation RC Data'!$O:$O, $A10, 'Deviation RC Data'!Z:Z, "x", 'Deviation RC Data'!$B:$B, ">=" & EDATE($B$1, -12), 'Deviation RC Data'!$B:$B, "<=" & $B$1 ), IF(_xlpm.result = 0, "", _xlpm.result) ) | M10: =_xlfn.LET( _xlpm.result, COUNTIFS( 'Deviation RC Data'!$O:$O, $A10, 'Deviation RC Data'!AA:AA, "x", 'Deviation RC Data'!$B:$B, ">=" & EDATE($B$1, -12), 'Deviation RC Data'!$B:$B, "<=" & $B$1 ), IF(_xlpm.result = 0, "", _xlpm.result) ) | N10: =_xlfn.LET( _xlpm.result, COUNTIFS( 'Deviation RC Data'!$O:$O, $A10, 'Deviation RC Data'!AB:AB, "x", 'Deviation RC Data'!$B:$B, ">=" & EDATE($B$1, -12), 'Deviation RC Data'!$B:$B, "<=" & $B$1 ), IF(_xlpm.result = 0, "", _xlpm.result) ) | O10: =_xlfn.LET( _xlpm.result, COUNTIFS( 'Deviation RC Data'!$O:$O, $A10, 'Deviation RC Data'!AC:AC, "x", 'Deviation RC Data'!$B:$B, ">=" & EDATE($B$1, -12), 'Deviation RC Data'!$B:$B, "<=" & $B$1 ), IF(_xlpm.result = 0, "", _xlpm.result) ) | P10: =_xlfn.LET( _xlpm.result, COUNTIFS( 'Deviation RC Data'!$O:$O, $A10, 'Deviation RC Data'!AD:AD, "x", 'Deviation RC Data'!$B:$B, ">=" & EDATE($B$1, -12), 'Deviation RC Data'!$B:$B, "<=" & $B$1 ), IF(_xlpm.result = 0, "", _xlpm.result) ) | Q10: =_xlfn.LET( _xlpm.result, COUNTIFS( 'Deviation RC Data'!$O:$O, $A10, 'Deviation RC Data'!AE:AE, "x", 'Deviation RC Data'!$B:$B, ">=" & EDATE($B$1, -12), 'Deviation RC Data'!$B:$B, "<=" & $B$1 ), IF(_xlpm.result = 0, "", _xlpm.result) ) | R10: =_xlfn.LET( _xlpm.result, COUNTIFS( 'Deviation RC Data'!$O:$O, $A10, 'Deviation RC Data'!AF:AF, "x", 'Deviation RC Data'!$B:$B, ">=" & EDATE($B$1, -12), 'Deviation RC Data'!$B:$B, "<=" & $B$1 ), IF(_xlpm.result = 0, "", _xlpm.result) ) | S10: =_xlfn.LET( _xlpm.result, COUNTIFS( 'Deviation RC Data'!$O:$O, $A10, 'Deviation RC Data'!AG:AG, "x", 'Deviation RC Data'!$B:$B, ">=" & EDATE($B$1, -12), 'Deviation RC Data'!$B:$B, "<=" & $B$1 ), IF(_xlpm.result = 0, "", _xlpm.result) ) | T10: =_xlfn.LET( _xlpm.result, COUNTIFS( 'Deviation RC Data'!$O:$O, $A10, 'Deviation RC Data'!AH:AH, "x", 'Deviation RC Data'!$B:$B, ">=" & EDATE($B$1, -12), 'Deviation RC Data'!$B:$B, "<=" & $B$1 ), IF(_xlpm.result = 0, "", _xlpm.result) )
A11: Temperature Excursion | B11: =_xlfn.LET( _xlpm.result, COUNTIFS( 'Deviation RC Data'!$O:$O, $A11, 'Deviation RC Data'!P:P, "x", 'Deviation RC Data'!$B:$B, ">=" & EDATE($B$1, -12), 'Deviation RC Data'!$B:$B, "<=" & $B$1 ), IF(_xlpm.result = 0, "", _xlpm.result) ) | C11: =_xlfn.LET( _xlpm.result, COUNTIFS( 'Deviation RC Data'!$O:$O, $A11, 'Deviation RC Data'!Q:Q, "x", 'Deviation RC Data'!$B:$B, ">=" & EDATE($B$1, -12), 'Deviation RC Data'!$B:$B, "<=" & $B$1 ), IF(_xlpm.result = 0, "", _xlpm.result) ) | D11: =_xlfn.LET( _xlpm.result, COUNTIFS( 'Deviation RC Data'!$O:$O, $A11, 'Deviation RC Data'!R:R, "x", 'Deviation RC Data'!$B:$B, ">=" & EDATE($B$1, -12), 'Deviation RC Data'!$B:$B, "<=" & $B$1 ), IF(_xlpm.result = 0, "", _xlpm.result) ) | E11: =_xlfn.LET( _xlpm.result, COUNTIFS( 'Deviation RC Data'!$O:$O, $A11, 'Deviation RC Data'!S:S, "x", 'Deviation RC Data'!$B:$B, ">=" & EDATE($B$1, -12), 'Deviation RC Data'!$B:$B, "<=" & $B$1 ), IF(_xlpm.result = 0, "", _xlpm.result) ) | F11: =_xlfn.LET( _xlpm.result, COUNTIFS( 'Deviation RC Data'!$O:$O, $A11, 'Deviation RC Data'!T:T, "x", 'Deviation RC Data'!$B:$B, ">=" & EDATE($B$1, -12), 'Deviation RC Data'!$B:$B, "<=" & $B$1 ), IF(_xlpm.result = 0, "", _xlpm.result) ) | G11: =_xlfn.LET( _xlpm.result, COUNTIFS( 'Deviation RC Data'!$O:$O, $A11, 'Deviation RC Data'!U:U, "x", 'Deviation RC Data'!$B:$B, ">=" & EDATE($B$1, -12), 'Deviation RC Data'!$B:$B, "<=" & $B$1 ), IF(_xlpm.result = 0, "", _xlpm.result) ) | H11: =_xlfn.LET( _xlpm.result, COUNTIFS( 'Deviation RC Data'!$O:$O, $A11, 'Deviation RC Data'!V:V, "x", 'Deviation RC Data'!$B:$B, ">=" & EDATE($B$1, -12), 'Deviation RC Data'!$B:$B, "<=" & $B$1 ), IF(_xlpm.result = 0, "", _xlpm.result) ) | I11: =_xlfn.LET( _xlpm.result, COUNTIFS( 'Deviation RC Data'!$O:$O, $A11, 'Deviation RC Data'!W:W, "x", 'Deviation RC Data'!$B:$B, ">=" & EDATE($B$1, -12), 'Deviation RC Data'!$B:$B, "<=" & $B$1 ), IF(_xlpm.result = 0, "", _xlpm.result) ) -> 1 | J11: =_xlfn.LET( _xlpm.result, COUNTIFS( 'Deviation RC Data'!$O:$O, $A11, 'Deviation RC Data'!X:X, "x", 'Deviation RC Data'!$B:$B, ">=" & EDATE($B$1, -12), 'Deviation RC Data'!$B:$B, "<=" & $B$1 ), IF(_xlpm.result = 0, "", _xlpm.result) ) | K11: =_xlfn.LET( _xlpm.result, COUNTIFS( 'Deviation RC Data'!$O:$O, $A11, 'Deviation RC Data'!Y:Y, "x", 'Deviation RC Data'!$B:$B, ">=" & EDATE($B$1, -12), 'Deviation RC Data'!$B:$B, "<=" & $B$1 ), IF(_xlpm.result = 0, "", _xlpm.result) ) | L11: =_xlfn.LET( _xlpm.result, COUNTIFS( 'Deviation RC Data'!$O:$O, $A11, 'Deviation RC Data'!Z:Z, "x", 'Deviation RC Data'!$B:$B, ">=" & EDATE($B$1, -12), 'Deviation RC Data'!$B:$B, "<=" & $B$1 ), IF(_xlpm.result = 0, "", _xlpm.result) ) | M11: =_xlfn.LET( _xlpm.result, COUNTIFS( 'Deviation RC Data'!$O:$O, $A11, 'Deviation RC Data'!AA:AA, "x", 'Deviation RC Data'!$B:$B, ">=" & EDATE($B$1, -12), 'Deviation RC Data'!$B:$B, "<=" & $B$1 ), IF(_xlpm.result = 0, "", _xlpm.result) ) | N11: =_xlfn.LET( _xlpm.result, COUNTIFS( 'Deviation RC Data'!$O:$O, $A11, 'Deviation RC Data'!AB:AB, "x", 'Deviation RC Data'!$B:$B, ">=" & EDATE($B$1, -12), 'Deviation RC Data'!$B:$B, "<=" & $B$1 ), IF(_xlpm.result = 0, "", _xlpm.result) ) | O11: =_xlfn.LET( _xlpm.result, COUNTIFS( 'Deviation RC Data'!$O:$O, $A11, 'Deviation RC Data'!AC:AC, "x", 'Deviation RC Data'!$B:$B, ">=" & EDATE($B$1, -12), 'Deviation RC Data'!$B:$B, "<=" & $B$1 ), IF(_xlpm.result = 0, "", _xlpm.result) ) | P11: =_xlfn.LET( _xlpm.result, COUNTIFS( 'Deviation RC Data'!$O:$O, $A11, 'Deviation RC Data'!AD:AD, "x", 'Deviation RC Data'!$B:$B, ">=" & EDATE($B$1, -12), 'Deviation RC Data'!$B:$B, "<=" & $B$1 ), IF(_xlpm.result = 0, "", _xlpm.result) ) | Q11: =_xlfn.LET( _xlpm.result, COUNTIFS( 'Deviation RC Data'!$O:$O, $A11, 'Deviation RC Data'!AE:AE, "x", 'Deviation RC Data'!$B:$B, ">=" & EDATE($B$1, -12), 'Deviation RC Data'!$B:$B, "<=" & $B$1 ), IF(_xlpm.result = 0, "", _xlpm.result) ) | R11: =_xlfn.LET( _xlpm.result, COUNTIFS( 'Deviation RC Data'!$O:$O, $A11, 'Deviation RC Data'!AF:AF, "x", 'Deviation RC Data'!$B:$B, ">=" & EDATE($B$1, -12), 'Deviation RC Data'!$B:$B, "<=" & $B$1 ), IF(_xlpm.result = 0, "", _xlpm.result) ) | S11: =_xlfn.LET( _xlpm.result, COUNTIFS( 'Deviation RC Data'!$O:$O, $A11, 'Deviation RC Data'!AG:AG, "x", 'Deviation RC Data'!$B:$B, ">=" & EDATE($B$1, -12), 'Deviation RC Data'!$B:$B, "<=" & $B$1 ), IF(_xlpm.result = 0, "", _xlpm.result) ) | T11: =_xlfn.LET( _xlpm.result, COUNTIFS( 'Deviation RC Data'!$O:$O, $A11, 'Deviation RC Data'!AH:AH, "x", 'Deviation RC Data'!$B:$B, ">=" & EDATE($B$1, -12), 'Deviation RC Data'!$B:$B, "<=" & $B$1 ), IF(_xlpm.result = 0, "", _xlpm.result) )
A12: Labelling | B12: =_xlfn.LET( _xlpm.result, COUNTIFS( 'Deviation RC Data'!$O:$O, $A12, 'Deviation RC Data'!P:P, "x", 'Deviation RC Data'!$B:$B, ">=" & EDATE($B$1, -12), 'Deviation RC Data'!$B:$B, "<=" & $B$1 ), IF(_xlpm.result = 0, "", _xlpm.result) ) -> 1 | C12: =_xlfn.LET( _xlpm.result, COUNTIFS( 'Deviation RC Data'!$O:$O, $A12, 'Deviation RC Data'!Q:Q, "x", 'Deviation RC Data'!$B:$B, ">=" & EDATE($B$1, -12), 'Deviation RC Data'!$B:$B, "<=" & $B$1 ), IF(_xlpm.result = 0, "", _xlpm.result) ) | D12: =_xlfn.LET( _xlpm.result, COUNTIFS( 'Deviation RC Data'!$O:$O, $A12, 'Deviation RC Data'!R:R, "x", 'Deviation RC Data'!$B:$B, ">=" & EDATE($B$1, -12), 'Deviation RC Data'!$B:$B, "<=" & $B$1 ), IF(_xlpm.result = 0, "", _xlpm.result) ) | E12: =_xlfn.LET( _xlpm.result, COUNTIFS( 'Deviation RC Data'!$O:$O, $A12, 'Deviation RC Data'!S:S, "x", 'Deviation RC Data'!$B:$B, ">=" & EDATE($B$1, -12), 'Deviation RC Data'!$B:$B, "<=" & $B$1 ), IF(_xlpm.result = 0, "", _xlpm.result) ) | F12: =_xlfn.LET( _xlpm.result, COUNTIFS( 'Deviation RC Data'!$O:$O, $A12, 'Deviation RC Data'!T:T, "x", 'Deviation RC Data'!$B:$B, ">=" & EDATE($B$1, -12), 'Deviation RC Data'!$B:$B, "<=" & $B$1 ), IF(_xlpm.result = 0, "", _xlpm.result) ) | G12: =_xlfn.LET( _xlpm.result, COUNTIFS( 'Deviation RC Data'!$O:$O, $A12, 'Deviation RC Data'!U:U, "x", 'Deviation RC Data'!$B:$B, ">=" & EDATE($B$1, -12), 'Deviation RC Data'!$B:$B, "<=" & $B$1 ), IF(_xlpm.result = 0, "", _xlpm.result) ) | H12: =_xlfn.LET( _xlpm.result, COUNTIFS( 'Deviation RC Data'!$O:$O, $A12, 'Deviation RC Data'!V:V, "x", 'Deviation RC Data'!$B:$B, ">=" & EDATE($B$1, -12), 'Deviation RC Data'!$B:$B, "<=" & $B$1 ), IF(_xlpm.result = 0, "", _xlpm.result) ) -> 2 | I12: =_xlfn.LET( _xlpm.result, COUNTIFS( 'Deviation RC Data'!$O:$O, $A12, 'Deviation RC Data'!W:W, "x", 'Deviation RC Data'!$B:$B, ">=" & EDATE($B$1, -12), 'Deviation RC Data'!$B:$B, "<=" & $B$1 ), IF(_xlpm.result = 0, "", _xlpm.result) ) | J12: =_xlfn.LET( _xlpm.result, COUNTIFS( 'Deviation RC Data'!$O:$O, $A12, 'Deviation RC Data'!X:X, "x", 'Deviation RC Data'!$B:$B, ">=" & EDATE($B$1, -12), 'Deviation RC Data'!$B:$B, "<=" & $B$1 ), IF(_xlpm.result = 0, "", _xlpm.result) ) | K12: =_xlfn.LET( _xlpm.result, COUNTIFS( 'Deviation RC Data'!$O:$O, $A12, 'Deviation RC Data'!Y:Y, "x", 'Deviation RC Data'!$B:$B, ">=" & EDATE($B$1, -12), 'Deviation RC Data'!$B:$B, "<=" & $B$1 ), IF(_xlpm.result = 0, "", _xlpm.result) ) | L12: =_xlfn.LET( _xlpm.result, COUNTIFS( 'Deviation RC Data'!$O:$O, $A12, 'Deviation RC Data'!Z:Z, "x", 'Deviation RC Data'!$B:$B, ">=" & EDATE($B$1, -12), 'Deviation RC Data'!$B:$B, "<=" & $B$1 ), IF(_xlpm.result = 0, "", _xlpm.result) ) | M12: =_xlfn.LET( _xlpm.result, COUNTIFS( 'Deviation RC Data'!$O:$O, $A12, 'Deviation RC Data'!AA:AA, "x", 'Deviation RC Data'!$B:$B, ">=" & EDATE($B$1, -12), 'Deviation RC Data'!$B:$B, "<=" & $B$1 ), IF(_xlpm.result = 0, "", _xlpm.result) ) | N12: =_xlfn.LET( _xlpm.result, COUNTIFS( 'Deviation RC Data'!$O:$O, $A12, 'Deviation RC Data'!AB:AB, "x", 'Deviation RC Data'!$B:$B, ">=" & EDATE($B$1, -12), 'Deviation RC Data'!$B:$B, "<=" & $B$1 ), IF(_xlpm.result = 0, "", _xlpm.result) ) | O12: =_xlfn.LET( _xlpm.result, COUNTIFS( 'Deviation RC Data'!$O:$O, $A12, 'Deviation RC Data'!AC:AC, "x", 'Deviation RC Data'!$B:$B, ">=" & EDATE($B$1, -12), 'Deviation RC Data'!$B:$B, "<=" & $B$1 ), IF(_xlpm.result = 0, "", _xlpm.result) ) | P12: =_xlfn.LET( _xlpm.result, COUNTIFS( 'Deviation RC Data'!$O:$O, $A12, 'Deviation RC Data'!AD:AD, "x", 'Deviation RC Data'!$B:$B, ">=" & EDATE($B$1, -12), 'Deviation RC Data'!$B:$B, "<=" & $B$1 ), IF(_xlpm.result = 0, "", _xlpm.result) ) | Q12: =_xlfn.LET( _xlpm.result, COUNTIFS( 'Deviation RC Data'!$O:$O, $A12, 'Deviation RC Data'!AE:AE, "x", 'Deviation RC Data'!$B:$B, ">=" & EDATE($B$1, -12), 'Deviation RC Data'!$B:$B, "<=" & $B$1 ), IF(_xlpm.result = 0, "", _xlpm.result) ) | R12: =_xlfn.LET( _xlpm.result, COUNTIFS( 'Deviation RC Data'!$O:$O, $A12, 'Deviation RC Data'!AF:AF, "x", 'Deviation RC Data'!$B:$B, ">=" & EDATE($B$1, -12), 'Deviation RC Data'!$B:$B, "<=" & $B$1 ), IF(_xlpm.result = 0, "", _xlpm.result) ) | S12: =_xlfn.LET( _xlpm.result, COUNTIFS( 'Deviation RC Data'!$O:$O, $A12, 'Deviation RC Data'!AG:AG, "x", 'Deviation RC Data'!$B:$B, ">=" & EDATE($B$1, -12), 'Deviation RC Data'!$B:$B, "<=" & $B$1 ), IF(_xlpm.result = 0, "", _xlpm.result) ) | T12: =_xlfn.LET( _xlpm.result, COUNTIFS( 'Deviation RC Data'!$O:$O, $A12, 'Deviation RC Data'!AH:AH, "x", 'Deviation RC Data'!$B:$B, ">=" & EDATE($B$1, -12), 'Deviation RC Data'!$B:$B, "<=" & $B$1 ), IF(_xlpm.result = 0, "", _xlpm.result) )
A13: Cleaning | B13: =_xlfn.LET( _xlpm.result, COUNTIFS( 'Deviation RC Data'!$O:$O, $A13, 'Deviation RC Data'!P:P, "x", 'Deviation RC Data'!$B:$B, ">=" & EDATE($B$1, -12), 'Deviation RC Data'!$B:$B, "<=" & $B$1 ), IF(_xlpm.result = 0, "", _xlpm.result) ) | C13: =_xlfn.LET( _xlpm.result, COUNTIFS( 'Deviation RC Data'!$O:$O, $A13, 'Deviation RC Data'!Q:Q, "x", 'Deviation RC Data'!$B:$B, ">=" & EDATE($B$1, -12), 'Deviation RC Data'!$B:$B, "<=" & $B$1 ), IF(_xlpm.result = 0, "", _xlpm.result) ) | D13: =_xlfn.LET( _xlpm.result, COUNTIFS( 'Deviation RC Data'!$O:$O, $A13, 'Deviation RC Data'!R:R, "x", 'Deviation RC Data'!$B:$B, ">=" & EDATE($B$1, -12), 'Deviation RC Data'!$B:$B, "<=" & $B$1 ), IF(_xlpm.result = 0, "", _xlpm.result) ) | E13: =_xlfn.LET( _xlpm.result, COUNTIFS( 'Deviation RC Data'!$O:$O, $A13, 'Deviation RC Data'!S:S, "x", 'Deviation RC Data'!$B:$B, ">=" & EDATE($B$1, -12), 'Deviation RC Data'!$B:$B, "<=" & $B$1 ), IF(_xlpm.result = 0, "", _xlpm.result) ) | F13: =_xlfn.LET( _xlpm.result, COUNTIFS( 'Deviation RC Data'!$O:$O, $A13, 'Deviation RC Data'!T:T, "x", 'Deviation RC Data'!$B:$B, ">=" & EDATE($B$1, -12), 'Deviation RC Data'!$B:$B, "<=" & $B$1 ), IF(_xlpm.result = 0, "", _xlpm.result) ) | G13: =_xlfn.LET( _xlpm.result, COUNTIFS( 'Deviation RC Data'!$O:$O, $A13, 'Deviation RC Data'!U:U, "x", 'Deviation RC Data'!$B:$B, ">=" & EDATE($B$1, -12), 'Deviation RC Data'!$B:$B, "<=" & $B$1 ), IF(_xlpm.result = 0, "", _xlpm.result) ) | H13: =_xlfn.LET( _xlpm.result, COUNTIFS( 'Deviation RC Data'!$O:$O, $A13, 'Deviation RC Data'!V:V, "x", 'Deviation RC Data'!$B:$B, ">=" & EDATE($B$1, -12), 'Deviation RC Data'!$B:$B, "<=" & $B$1 ), IF(_xlpm.result = 0, "", _xlpm.result) ) | I13: =_xlfn.LET( _xlpm.result, COUNTIFS( 'Deviation RC Data'!$O:$O, $A13, 'Deviation RC Data'!W:W, "x", 'Deviation RC Data'!$B:$B, ">=" & EDATE($B$1, -12), 'Deviation RC Data'!$B:$B, "<=" & $B$1 ), IF(_xlpm.result = 0, "", _xlpm.result) ) | J13: =_xlfn.LET( _xlpm.result, COUNTIFS( 'Deviation RC Data'!$O:$O, $A13, 'Deviation RC Data'!X:X, "x", 'Deviation RC Data'!$B:$B, ">=" & EDATE($B$1, -12), 'Deviation RC Data'!$B:$B, "<=" & $B$1 ), IF(_xlpm.result = 0, "", _xlpm.result) ) | K13: =_xlfn.LET( _xlpm.result, COUNTIFS( 'Deviation RC Data'!$O:$O, $A13, 'Deviation RC Data'!Y:Y, "x", 'Deviation RC Data'!$B:$B, ">=" & EDATE($B$1, -12), 'Deviation RC Data'!$B:$B, "<=" & $B$1 ), IF(_xlpm.result = 0, "", _xlpm.result) ) | L13: =_xlfn.LET( _xlpm.result, COUNTIFS( 'Deviation RC Data'!$O:$O, $A13, 'Deviation RC Data'!Z:Z, "x", 'Deviation RC Data'!$B:$B, ">=" & EDATE($B$1, -12), 'Deviation RC Data'!$B:$B, "<=" & $B$1 ), IF(_xlpm.result = 0, "", _xlpm.result) ) | M13: =_xlfn.LET( _xlpm.result, COUNTIFS( 'Deviation RC Data'!$O:$O, $A13, 'Deviation RC Data'!AA:AA, "x", 'Deviation RC Data'!$B:$B, ">=" & EDATE($B$1, -12), 'Deviation RC Data'!$B:$B, "<=" & $B$1 ), IF(_xlpm.result = 0, "", _xlpm.result) ) | N13: =_xlfn.LET( _xlpm.result, COUNTIFS( 'Deviation RC Data'!$O:$O, $A13, 'Deviation RC Data'!AB:AB, "x", 'Deviation RC Data'!$B:$B, ">=" & EDATE($B$1, -12), 'Deviation RC Data'!$B:$B, "<=" & $B$1 ), IF(_xlpm.result = 0, "", _xlpm.result) ) | O13: =_xlfn.LET( _xlpm.result, COUNTIFS( 'Deviation RC Data'!$O:$O, $A13, 'Deviation RC Data'!AC:AC, "x", 'Deviation RC Data'!$B:$B, ">=" & EDATE($B$1, -12), 'Deviation RC Data'!$B:$B, "<=" & $B$1 ), IF(_xlpm.result = 0, "", _xlpm.result) ) | P13: =_xlfn.LET( _xlpm.result, COUNTIFS( 'Deviation RC Data'!$O:$O, $A13, 'Deviation RC Data'!AD:AD, "x", 'Deviation RC Data'!$B:$B, ">=" & EDATE($B$1, -12), 'Deviation RC Data'!$B:$B, "<=" & $B$1 ), IF(_xlpm.result = 0, "", _xlpm.result) ) | Q13: =_xlfn.LET( _xlpm.result, COUNTIFS( 'Deviation RC Data'!$O:$O, $A13, 'Deviation RC Data'!AE:AE, "x", 'Deviation RC Data'!$B:$B, ">=" & EDATE($B$1, -12), 'Deviation RC Data'!$B:$B, "<=" & $B$1 ), IF(_xlpm.result = 0, "", _xlpm.result) ) | R13: =_xlfn.LET( _xlpm.result, COUNTIFS( 'Deviation RC Data'!$O:$O, $A13, 'Deviation RC Data'!AF:AF, "x", 'Deviation RC Data'!$B:$B, ">=" & EDATE($B$1, -12), 'Deviation RC Data'!$B:$B, "<=" & $B$1 ), IF(_xlpm.result = 0, "", _xlpm.result) ) | S13: =_xlfn.LET( _xlpm.result, COUNTIFS( 'Deviation RC Data'!$O:$O, $A13, 'Deviation RC Data'!AG:AG, "x", 'Deviation RC Data'!$B:$B, ">=" & EDATE($B$1, -12), 'Deviation RC Data'!$B:$B, "<=" & $B$1 ), IF(_xlpm.result = 0, "", _xlpm.result) ) | T13: =_xlfn.LET( _xlpm.result, COUNTIFS( 'Deviation RC Data'!$O:$O, $A13, 'Deviation RC Data'!AH:AH, "x", 'Deviation RC Data'!$B:$B, ">=" & EDATE($B$1, -12), 'Deviation RC Data'!$B:$B, "<=" & $B$1 ), IF(_xlpm.result = 0, "", _xlpm.result) )
